2025-10-07 04:56:37,353 - task_manager - CRITICAL - C:\Users\pmokr\OneDrive\Рабочий стол\task-manager\src\app\exceptions\decorators.py:47 - Unexpected server error: send_notification_task() got an unexpected keyword argument 'recipient', traceback=<traceback object at 0x000001D4EA305EC0>
2025-10-07 04:56:37,353 - task_manager - CRITICAL - C:\Users\pmokr\OneDrive\Рабочий стол\task-manager\src\app\exceptions\decorators.py:47 - Unexpected server error: send_notification_task() got an unexpected keyword argument 'recipient', traceback=<traceback object at 0x000001D4EA305EC0>
2025-10-08 00:34:55,347 - task_manager - CRITICAL - C:\Users\pmokr\OneDrive\Рабочий стол\task-manager\src\app\exceptions\decorators.py:47 - Unexpected server error: AppBaseException.__init__() got an unexpected keyword argument 'detail', traceback=<traceback object at 0x000002EC4341A7C0>
2025-10-08 00:34:55,347 - task_manager - CRITICAL - C:\Users\pmokr\OneDrive\Рабочий стол\task-manager\src\app\exceptions\decorators.py:47 - Unexpected server error: AppBaseException.__init__() got an unexpected keyword argument 'detail', traceback=<traceback object at 0x000002EC4341A7C0>
2025-10-26 23:33:54,071 - task_manager - CRITICAL - c:\Users\pmokr\OneDrive\Рабочий стол\task-manager\src\app\exceptions\decorators.py:47 - Unexpected server error: password cannot be longer than 72 bytes, truncate manually if necessary (e.g. my_password[:72]), traceback=<traceback object at 0x000002552765B140>
2025-10-26 23:33:54,071 - task_manager - CRITICAL - c:\Users\pmokr\OneDrive\Рабочий стол\task-manager\src\app\exceptions\decorators.py:47 - Unexpected server error: password cannot be longer than 72 bytes, truncate manually if necessary (e.g. my_password[:72]), traceback=<traceback object at 0x000002552765B140>
2025-10-26 23:33:55,893 - task_manager - CRITICAL - c:\Users\pmokr\OneDrive\Рабочий стол\task-manager\src\app\exceptions\decorators.py:47 - Unexpected server error: 'user' is not among the defined enum values. Enum name: role. Possible values: USER, ADMIN, traceback=<traceback object at 0x00000255278B6AC0>
2025-10-26 23:33:55,893 - task_manager - CRITICAL - c:\Users\pmokr\OneDrive\Рабочий стол\task-manager\src\app\exceptions\decorators.py:47 - Unexpected server error: 'user' is not among the defined enum values. Enum name: role. Possible values: USER, ADMIN, traceback=<traceback object at 0x00000255278B6AC0>
2025-10-26 23:36:39,011 - task_manager - CRITICAL - c:\Users\pmokr\OneDrive\Рабочий стол\task-manager\src\app\exceptions\decorators.py:47 - Unexpected server error: (sqlite3.IntegrityError) UNIQUE constraint failed: users.email
[SQL: INSERT INTO users (first_name, last_name, email, password_hash, role, active, id) VALUES (?, ?, ?, ?, ?, ?, ?) RETURNING created_at, updated_at]
[parameters: ('api', 'пользователь', 'api@example.com', b'$2b$12$f7v8TuEYbZP.flLT6v5Ej.7QAwKCOIRnRdOmmMYZ5szc4EFv4NdeW', 'user', 1, 'd4af555d78f34a9382f54acf27eb9bc0')]
(Background on this error at: https://sqlalche.me/e/20/gkpj), traceback=<traceback object at 0x0000023FB2C05A80>
2025-10-26 23:36:39,011 - task_manager - CRITICAL - c:\Users\pmokr\OneDrive\Рабочий стол\task-manager\src\app\exceptions\decorators.py:47 - Unexpected server error: (sqlite3.IntegrityError) UNIQUE constraint failed: users.email
[SQL: INSERT INTO users (first_name, last_name, email, password_hash, role, active, id) VALUES (?, ?, ?, ?, ?, ?, ?) RETURNING created_at, updated_at]
[parameters: ('api', 'пользователь', 'api@example.com', b'$2b$12$f7v8TuEYbZP.flLT6v5Ej.7QAwKCOIRnRdOmmMYZ5szc4EFv4NdeW', 'user', 1, 'd4af555d78f34a9382f54acf27eb9bc0')]
(Background on this error at: https://sqlalche.me/e/20/gkpj), traceback=<traceback object at 0x0000023FB2C05A80>
2025-10-26 23:36:40,710 - task_manager - CRITICAL - c:\Users\pmokr\OneDrive\Рабочий стол\task-manager\src\app\exceptions\decorators.py:47 - Unexpected server error: (sqlite3.IntegrityError) UNIQUE constraint failed: users.email
[SQL: INSERT INTO users (first_name, last_name, email, password_hash, role, active, id) VALUES (?, ?, ?, ?, ?, ?, ?) RETURNING created_at, updated_at]
[parameters: ('wrong', 'user', 'wrong@example.com', b'$2b$12$2z6IE/5/y2leQ65Zs1yUR.1SLMvNQ.nxCohcQJpWyxmSR544gndhu', 'user', 1, '7d1fb75d274048e39e2ced63c9bbdb70')]
(Background on this error at: https://sqlalche.me/e/20/gkpj), traceback=<traceback object at 0x0000023FB45880C0>
2025-10-26 23:36:40,710 - task_manager - CRITICAL - c:\Users\pmokr\OneDrive\Рабочий стол\task-manager\src\app\exceptions\decorators.py:47 - Unexpected server error: (sqlite3.IntegrityError) UNIQUE constraint failed: users.email
[SQL: INSERT INTO users (first_name, last_name, email, password_hash, role, active, id) VALUES (?, ?, ?, ?, ?, ?, ?) RETURNING created_at, updated_at]
[parameters: ('wrong', 'user', 'wrong@example.com', b'$2b$12$2z6IE/5/y2leQ65Zs1yUR.1SLMvNQ.nxCohcQJpWyxmSR544gndhu', 'user', 1, '7d1fb75d274048e39e2ced63c9bbdb70')]
(Background on this error at: https://sqlalche.me/e/20/gkpj), traceback=<traceback object at 0x0000023FB45880C0>
2025-10-26 23:36:41,993 - task_manager - CRITICAL - c:\Users\pmokr\OneDrive\Рабочий стол\task-manager\src\app\exceptions\decorators.py:47 - Unexpected server error: (sqlite3.IntegrityError) UNIQUE constraint failed: users.email
[SQL: INSERT INTO users (first_name, last_name, email, password_hash, role, active, id) VALUES (?, ?, ?, ?, ?, ?, ?) RETURNING created_at, updated_at]
[parameters: ('protected', 'user', 'protected@example.com', b'$2b$12$w7SX1mz0Utgq33Z.xXxQyOOZ.GRCORktk9XZw.GjQIy/Z5ff/VhDS', 'user', 1, '0f151adda59b49c0b342d23ad84a620a')]
(Background on this error at: https://sqlalche.me/e/20/gkpj), traceback=<traceback object at 0x0000023FB45A92C0>
2025-10-26 23:36:41,993 - task_manager - CRITICAL - c:\Users\pmokr\OneDrive\Рабочий стол\task-manager\src\app\exceptions\decorators.py:47 - Unexpected server error: (sqlite3.IntegrityError) UNIQUE constraint failed: users.email
[SQL: INSERT INTO users (first_name, last_name, email, password_hash, role, active, id) VALUES (?, ?, ?, ?, ?, ?, ?) RETURNING created_at, updated_at]
[parameters: ('protected', 'user', 'protected@example.com', b'$2b$12$w7SX1mz0Utgq33Z.xXxQyOOZ.GRCORktk9XZw.GjQIy/Z5ff/VhDS', 'user', 1, '0f151adda59b49c0b342d23ad84a620a')]
(Background on this error at: https://sqlalche.me/e/20/gkpj), traceback=<traceback object at 0x0000023FB45A92C0>
2025-10-26 23:36:43,818 - task_manager - CRITICAL - c:\Users\pmokr\OneDrive\Рабочий стол\task-manager\src\app\exceptions\decorators.py:47 - Unexpected server error: (sqlite3.IntegrityError) UNIQUE constraint failed: users.email
[SQL: INSERT INTO users (first_name, last_name, email, password_hash, role, active, id) VALUES (?, ?, ?, ?, ?, ?, ?) RETURNING created_at, updated_at]
[parameters: ('expired', 'user', 'expired@example.com', b'$2b$12$6Ef97.sL.K3IA/mmRM.4du/athjgTzuHDEDbccHOmVcs0KrG2mL.u', 'user', 1, '62f9096ac2ae43dc8f1a50b3df77bff1')]
(Background on this error at: https://sqlalche.me/e/20/gkpj), traceback=<traceback object at 0x0000023FB452B980>
2025-10-26 23:36:43,818 - task_manager - CRITICAL - c:\Users\pmokr\OneDrive\Рабочий стол\task-manager\src\app\exceptions\decorators.py:47 - Unexpected server error: (sqlite3.IntegrityError) UNIQUE constraint failed: users.email
[SQL: INSERT INTO users (first_name, last_name, email, password_hash, role, active, id) VALUES (?, ?, ?, ?, ?, ?, ?) RETURNING created_at, updated_at]
[parameters: ('expired', 'user', 'expired@example.com', b'$2b$12$6Ef97.sL.K3IA/mmRM.4du/athjgTzuHDEDbccHOmVcs0KrG2mL.u', 'user', 1, '62f9096ac2ae43dc8f1a50b3df77bff1')]
(Background on this error at: https://sqlalche.me/e/20/gkpj), traceback=<traceback object at 0x0000023FB452B980>
2025-10-26 23:36:45,474 - task_manager - CRITICAL - c:\Users\pmokr\OneDrive\Рабочий стол\task-manager\src\app\exceptions\decorators.py:47 - Unexpected server error: (sqlite3.IntegrityError) UNIQUE constraint failed: users.email
[SQL: INSERT INTO users (first_name, last_name, email, password_hash, role, active, id) VALUES (?, ?, ?, ?, ?, ?, ?) RETURNING created_at, updated_at]
[parameters: ('case', 'test', 'casetest@example.com', b'$2b$12$rcCqBCuAlfrSQPJubXtNlOV.iZWUw6ntuP7t97LHK7Qrwi4cqFAB2', 'user', 1, '9f658d0117c54f0c89dfe9eeaaf79fd9')]
(Background on this error at: https://sqlalche.me/e/20/gkpj), traceback=<traceback object at 0x0000023FB36C6780>
2025-10-26 23:36:45,474 - task_manager - CRITICAL - c:\Users\pmokr\OneDrive\Рабочий стол\task-manager\src\app\exceptions\decorators.py:47 - Unexpected server error: (sqlite3.IntegrityError) UNIQUE constraint failed: users.email
[SQL: INSERT INTO users (first_name, last_name, email, password_hash, role, active, id) VALUES (?, ?, ?, ?, ?, ?, ?) RETURNING created_at, updated_at]
[parameters: ('case', 'test', 'casetest@example.com', b'$2b$12$rcCqBCuAlfrSQPJubXtNlOV.iZWUw6ntuP7t97LHK7Qrwi4cqFAB2', 'user', 1, '9f658d0117c54f0c89dfe9eeaaf79fd9')]
(Background on this error at: https://sqlalche.me/e/20/gkpj), traceback=<traceback object at 0x0000023FB36C6780>
2025-10-26 23:36:46,582 - task_manager - CRITICAL - c:\Users\pmokr\OneDrive\Рабочий стол\task-manager\src\app\exceptions\decorators.py:47 - Unexpected server error: password cannot be longer than 72 bytes, truncate manually if necessary (e.g. my_password[:72]), traceback=<traceback object at 0x0000023FB4B6CC80>
2025-10-26 23:36:46,582 - task_manager - CRITICAL - c:\Users\pmokr\OneDrive\Рабочий стол\task-manager\src\app\exceptions\decorators.py:47 - Unexpected server error: password cannot be longer than 72 bytes, truncate manually if necessary (e.g. my_password[:72]), traceback=<traceback object at 0x0000023FB4B6CC80>
2025-10-26 23:36:46,929 - task_manager - CRITICAL - c:\Users\pmokr\OneDrive\Рабочий стол\task-manager\src\app\exceptions\decorators.py:47 - Unexpected server error: (sqlite3.IntegrityError) UNIQUE constraint failed: users.email
[SQL: INSERT INTO users (first_name, last_name, email, password_hash, role, active, id) VALUES (?, ?, ?, ?, ?, ?, ?) RETURNING created_at, updated_at]
[parameters: ('мин', 'пароль', 'minpassword@example.com', b'$2b$12$G3QeYDtCyG6T.0RlGyAM8ea/Rg25hCfRTiFi97NFPpRMf2Dhas3ye', 'user', 1, 'c63d22a8f50b4acbb2f61ea6ae996494')]
(Background on this error at: https://sqlalche.me/e/20/gkpj), traceback=<traceback object at 0x0000023FB2DE62C0>
2025-10-26 23:36:46,929 - task_manager - CRITICAL - c:\Users\pmokr\OneDrive\Рабочий стол\task-manager\src\app\exceptions\decorators.py:47 - Unexpected server error: (sqlite3.IntegrityError) UNIQUE constraint failed: users.email
[SQL: INSERT INTO users (first_name, last_name, email, password_hash, role, active, id) VALUES (?, ?, ?, ?, ?, ?, ?) RETURNING created_at, updated_at]
[parameters: ('мин', 'пароль', 'minpassword@example.com', b'$2b$12$G3QeYDtCyG6T.0RlGyAM8ea/Rg25hCfRTiFi97NFPpRMf2Dhas3ye', 'user', 1, 'c63d22a8f50b4acbb2f61ea6ae996494')]
(Background on this error at: https://sqlalche.me/e/20/gkpj), traceback=<traceback object at 0x0000023FB2DE62C0>
2025-10-26 23:36:47,539 - task_manager - CRITICAL - c:\Users\pmokr\OneDrive\Рабочий стол\task-manager\src\app\exceptions\decorators.py:47 - Unexpected server error: (sqlite3.IntegrityError) UNIQUE constraint failed: users.email
[SQL: INSERT INTO users (first_name, last_name, email, password_hash, role, active, id) VALUES (?, ?, ?, ?, ?, ?, ?) RETURNING created_at, updated_at]
[parameters: ('тест', 'обновление', 'update.extra@example.com', b'$2b$12$z2HVqCL3sgbzIPp1HvNQb.qkoeNrmaMfdWm9C1IVgPJ93oUvPqc/S', 'user', 1, '2a3046baca9d4d249e982d6e6961792d')]
(Background on this error at: https://sqlalche.me/e/20/gkpj), traceback=<traceback object at 0x0000023FB3691940>
2025-10-26 23:36:47,539 - task_manager - CRITICAL - c:\Users\pmokr\OneDrive\Рабочий стол\task-manager\src\app\exceptions\decorators.py:47 - Unexpected server error: (sqlite3.IntegrityError) UNIQUE constraint failed: users.email
[SQL: INSERT INTO users (first_name, last_name, email, password_hash, role, active, id) VALUES (?, ?, ?, ?, ?, ?, ?) RETURNING created_at, updated_at]
[parameters: ('тест', 'обновление', 'update.extra@example.com', b'$2b$12$z2HVqCL3sgbzIPp1HvNQb.qkoeNrmaMfdWm9C1IVgPJ93oUvPqc/S', 'user', 1, '2a3046baca9d4d249e982d6e6961792d')]
(Background on this error at: https://sqlalche.me/e/20/gkpj), traceback=<traceback object at 0x0000023FB3691940>
2025-10-26 23:36:47,928 - task_manager - CRITICAL - c:\Users\pmokr\OneDrive\Рабочий стол\task-manager\src\app\exceptions\decorators.py:47 - Unexpected server error: (sqlite3.IntegrityError) UNIQUE constraint failed: users.email
[SQL: INSERT INTO users (first_name, last_name, email, password_hash, role, active, id) VALUES (?, ?, ?, ?, ?, ?, ?) RETURNING created_at, updated_at]
[parameters: ('регистр', 'тест', 'casesensitive@example.com', b'$2b$12$RfO17nXa43Y3sQXBls1QD.R/o3NzPu0R64dVnsqZlb7Cf0ZbC.ZP.', 'user', 1, 'f5492f80e244491f89db152d9235ee5f')]
(Background on this error at: https://sqlalche.me/e/20/gkpj), traceback=<traceback object at 0x0000023FB2E02D40>
2025-10-26 23:36:47,928 - task_manager - CRITICAL - c:\Users\pmokr\OneDrive\Рабочий стол\task-manager\src\app\exceptions\decorators.py:47 - Unexpected server error: (sqlite3.IntegrityError) UNIQUE constraint failed: users.email
[SQL: INSERT INTO users (first_name, last_name, email, password_hash, role, active, id) VALUES (?, ?, ?, ?, ?, ?, ?) RETURNING created_at, updated_at]
[parameters: ('регистр', 'тест', 'casesensitive@example.com', b'$2b$12$RfO17nXa43Y3sQXBls1QD.R/o3NzPu0R64dVnsqZlb7Cf0ZbC.ZP.', 'user', 1, 'f5492f80e244491f89db152d9235ee5f')]
(Background on this error at: https://sqlalche.me/e/20/gkpj), traceback=<traceback object at 0x0000023FB2E02D40>
2025-10-26 23:36:49,111 - task_manager - CRITICAL - c:\Users\pmokr\OneDrive\Рабочий стол\task-manager\src\app\exceptions\decorators.py:47 - Unexpected server error: 'user' is not among the defined enum values. Enum name: role. Possible values: USER, ADMIN, traceback=<traceback object at 0x0000023FB30B3C00>
2025-10-26 23:36:49,111 - task_manager - CRITICAL - c:\Users\pmokr\OneDrive\Рабочий стол\task-manager\src\app\exceptions\decorators.py:47 - Unexpected server error: 'user' is not among the defined enum values. Enum name: role. Possible values: USER, ADMIN, traceback=<traceback object at 0x0000023FB30B3C00>
2025-10-26 23:36:50,315 - task_manager - CRITICAL - c:\Users\pmokr\OneDrive\Рабочий стол\task-manager\src\app\exceptions\decorators.py:47 - Unexpected server error: 'user' is not among the defined enum values. Enum name: role. Possible values: USER, ADMIN, traceback=<traceback object at 0x0000023FB47C0D40>
2025-10-26 23:36:50,315 - task_manager - CRITICAL - c:\Users\pmokr\OneDrive\Рабочий стол\task-manager\src\app\exceptions\decorators.py:47 - Unexpected server error: 'user' is not among the defined enum values. Enum name: role. Possible values: USER, ADMIN, traceback=<traceback object at 0x0000023FB47C0D40>
2025-10-26 23:36:50,674 - task_manager - CRITICAL - c:\Users\pmokr\OneDrive\Рабочий стол\task-manager\src\app\exceptions\decorators.py:47 - Unexpected server error: 'user' is not among the defined enum values. Enum name: role. Possible values: USER, ADMIN, traceback=<traceback object at 0x0000023FB36E1C00>
2025-10-26 23:36:50,674 - task_manager - CRITICAL - c:\Users\pmokr\OneDrive\Рабочий стол\task-manager\src\app\exceptions\decorators.py:47 - Unexpected server error: 'user' is not among the defined enum values. Enum name: role. Possible values: USER, ADMIN, traceback=<traceback object at 0x0000023FB36E1C00>
2025-10-26 23:36:51,001 - task_manager - CRITICAL - c:\Users\pmokr\OneDrive\Рабочий стол\task-manager\src\app\exceptions\decorators.py:47 - Unexpected server error: 'user' is not among the defined enum values. Enum name: role. Possible values: USER, ADMIN, traceback=<traceback object at 0x0000023FB486BA40>
2025-10-26 23:36:51,001 - task_manager - CRITICAL - c:\Users\pmokr\OneDrive\Рабочий стол\task-manager\src\app\exceptions\decorators.py:47 - Unexpected server error: 'user' is not among the defined enum values. Enum name: role. Possible values: USER, ADMIN, traceback=<traceback object at 0x0000023FB486BA40>
2025-10-26 23:36:51,497 - task_manager - CRITICAL - c:\Users\pmokr\OneDrive\Рабочий стол\task-manager\src\app\exceptions\decorators.py:47 - Unexpected server error: 'user' is not among the defined enum values. Enum name: role. Possible values: USER, ADMIN, traceback=<traceback object at 0x0000023FB47CC440>
2025-10-26 23:36:51,497 - task_manager - CRITICAL - c:\Users\pmokr\OneDrive\Рабочий стол\task-manager\src\app\exceptions\decorators.py:47 - Unexpected server error: 'user' is not among the defined enum values. Enum name: role. Possible values: USER, ADMIN, traceback=<traceback object at 0x0000023FB47CC440>
2025-10-26 23:45:33,718 - task_manager - CRITICAL - c:\Users\pmokr\OneDrive\Рабочий стол\task-manager\src\app\exceptions\decorators.py:47 - Unexpected server error: (sqlite3.IntegrityError) UNIQUE constraint failed: users.email
[SQL: INSERT INTO users (first_name, last_name, email, password_hash, role, active, id) VALUES (?, ?, ?, ?, ?, ?, ?) RETURNING created_at, updated_at]
[parameters: ('api', 'пользователь', 'api@example.com', b'$2b$12$hLFP99rOqyhX8hsTiFJIROLF4Xu6yGk42o3tig8aAC8o5GmHEeaZa', 'user', 1, 'aad26ea226f04177b58dfead50255b87')]
(Background on this error at: https://sqlalche.me/e/20/gkpj), traceback=<traceback object at 0x00000221762A1BC0>
2025-10-26 23:45:33,718 - task_manager - CRITICAL - c:\Users\pmokr\OneDrive\Рабочий стол\task-manager\src\app\exceptions\decorators.py:47 - Unexpected server error: (sqlite3.IntegrityError) UNIQUE constraint failed: users.email
[SQL: INSERT INTO users (first_name, last_name, email, password_hash, role, active, id) VALUES (?, ?, ?, ?, ?, ?, ?) RETURNING created_at, updated_at]
[parameters: ('api', 'пользователь', 'api@example.com', b'$2b$12$hLFP99rOqyhX8hsTiFJIROLF4Xu6yGk42o3tig8aAC8o5GmHEeaZa', 'user', 1, 'aad26ea226f04177b58dfead50255b87')]
(Background on this error at: https://sqlalche.me/e/20/gkpj), traceback=<traceback object at 0x00000221762A1BC0>
2025-10-26 23:45:35,200 - task_manager - CRITICAL - c:\Users\pmokr\OneDrive\Рабочий стол\task-manager\src\app\exceptions\decorators.py:47 - Unexpected server error: (sqlite3.IntegrityError) UNIQUE constraint failed: users.email
[SQL: INSERT INTO users (first_name, last_name, email, password_hash, role, active, id) VALUES (?, ?, ?, ?, ?, ?, ?) RETURNING created_at, updated_at]
[parameters: ('wrong', 'user', 'wrong@example.com', b'$2b$12$oMFmdmRJGtBpThnYTAvXOuIVeDKoyJOrQgQbWMKvNqR3ZkKmFxPqi', 'user', 1, '12c31e6774de4d5281562e1d49a00298')]
(Background on this error at: https://sqlalche.me/e/20/gkpj), traceback=<traceback object at 0x0000022177C2C2C0>
2025-10-26 23:45:35,200 - task_manager - CRITICAL - c:\Users\pmokr\OneDrive\Рабочий стол\task-manager\src\app\exceptions\decorators.py:47 - Unexpected server error: (sqlite3.IntegrityError) UNIQUE constraint failed: users.email
[SQL: INSERT INTO users (first_name, last_name, email, password_hash, role, active, id) VALUES (?, ?, ?, ?, ?, ?, ?) RETURNING created_at, updated_at]
[parameters: ('wrong', 'user', 'wrong@example.com', b'$2b$12$oMFmdmRJGtBpThnYTAvXOuIVeDKoyJOrQgQbWMKvNqR3ZkKmFxPqi', 'user', 1, '12c31e6774de4d5281562e1d49a00298')]
(Background on this error at: https://sqlalche.me/e/20/gkpj), traceback=<traceback object at 0x0000022177C2C2C0>
2025-10-26 23:45:36,231 - task_manager - CRITICAL - c:\Users\pmokr\OneDrive\Рабочий стол\task-manager\src\app\exceptions\decorators.py:47 - Unexpected server error: (sqlite3.IntegrityError) UNIQUE constraint failed: users.email
[SQL: INSERT INTO users (first_name, last_name, email, password_hash, role, active, id) VALUES (?, ?, ?, ?, ?, ?, ?) RETURNING created_at, updated_at]
[parameters: ('protected', 'user', 'protected@example.com', b'$2b$12$ns6AHG/YAEx8mAZnYDDfP.HSh7Xi3y/K7bjlRRJ6vg9MX0Yz/BnsO', 'user', 1, '713b641635634aa4995abb4e63be69dc')]
(Background on this error at: https://sqlalche.me/e/20/gkpj), traceback=<traceback object at 0x0000022177E874C0>
2025-10-26 23:45:36,231 - task_manager - CRITICAL - c:\Users\pmokr\OneDrive\Рабочий стол\task-manager\src\app\exceptions\decorators.py:47 - Unexpected server error: (sqlite3.IntegrityError) UNIQUE constraint failed: users.email
[SQL: INSERT INTO users (first_name, last_name, email, password_hash, role, active, id) VALUES (?, ?, ?, ?, ?, ?, ?) RETURNING created_at, updated_at]
[parameters: ('protected', 'user', 'protected@example.com', b'$2b$12$ns6AHG/YAEx8mAZnYDDfP.HSh7Xi3y/K7bjlRRJ6vg9MX0Yz/BnsO', 'user', 1, '713b641635634aa4995abb4e63be69dc')]
(Background on this error at: https://sqlalche.me/e/20/gkpj), traceback=<traceback object at 0x0000022177E874C0>
2025-10-26 23:45:37,554 - task_manager - CRITICAL - c:\Users\pmokr\OneDrive\Рабочий стол\task-manager\src\app\exceptions\decorators.py:47 - Unexpected server error: (sqlite3.IntegrityError) UNIQUE constraint failed: users.email
[SQL: INSERT INTO users (first_name, last_name, email, password_hash, role, active, id) VALUES (?, ?, ?, ?, ?, ?, ?) RETURNING created_at, updated_at]
[parameters: ('expired', 'user', 'expired@example.com', b'$2b$12$opYhARFoxashpAU4Kxsqb.aESzZOCBp3dKazhxq/1buJVeptyOHTy', 'user', 1, '773281f6520f438fa3a6bfc8dc1b7816')]
(Background on this error at: https://sqlalche.me/e/20/gkpj), traceback=<traceback object at 0x00000221768CBC80>
2025-10-26 23:45:37,554 - task_manager - CRITICAL - c:\Users\pmokr\OneDrive\Рабочий стол\task-manager\src\app\exceptions\decorators.py:47 - Unexpected server error: (sqlite3.IntegrityError) UNIQUE constraint failed: users.email
[SQL: INSERT INTO users (first_name, last_name, email, password_hash, role, active, id) VALUES (?, ?, ?, ?, ?, ?, ?) RETURNING created_at, updated_at]
[parameters: ('expired', 'user', 'expired@example.com', b'$2b$12$opYhARFoxashpAU4Kxsqb.aESzZOCBp3dKazhxq/1buJVeptyOHTy', 'user', 1, '773281f6520f438fa3a6bfc8dc1b7816')]
(Background on this error at: https://sqlalche.me/e/20/gkpj), traceback=<traceback object at 0x00000221768CBC80>
2025-10-26 23:45:38,607 - task_manager - CRITICAL - c:\Users\pmokr\OneDrive\Рабочий стол\task-manager\src\app\exceptions\decorators.py:47 - Unexpected server error: (sqlite3.IntegrityError) UNIQUE constraint failed: users.email
[SQL: INSERT INTO users (first_name, last_name, email, password_hash, role, active, id) VALUES (?, ?, ?, ?, ?, ?, ?) RETURNING created_at, updated_at]
[parameters: ('case', 'test', 'casetest@example.com', b'$2b$12$bhNzXDzPqMZMAxLFZlgLU.C.YbwUL4ONeXX9nU07gRTR7iZ2bWvw6', 'user', 1, 'ae7eb014667e427abfa648158c865fa6')]
(Background on this error at: https://sqlalche.me/e/20/gkpj), traceback=<traceback object at 0x0000022177EC38C0>
2025-10-26 23:45:38,607 - task_manager - CRITICAL - c:\Users\pmokr\OneDrive\Рабочий стол\task-manager\src\app\exceptions\decorators.py:47 - Unexpected server error: (sqlite3.IntegrityError) UNIQUE constraint failed: users.email
[SQL: INSERT INTO users (first_name, last_name, email, password_hash, role, active, id) VALUES (?, ?, ?, ?, ?, ?, ?) RETURNING created_at, updated_at]
[parameters: ('case', 'test', 'casetest@example.com', b'$2b$12$bhNzXDzPqMZMAxLFZlgLU.C.YbwUL4ONeXX9nU07gRTR7iZ2bWvw6', 'user', 1, 'ae7eb014667e427abfa648158c865fa6')]
(Background on this error at: https://sqlalche.me/e/20/gkpj), traceback=<traceback object at 0x0000022177EC38C0>
2025-10-26 23:45:39,375 - task_manager - CRITICAL - c:\Users\pmokr\OneDrive\Рабочий стол\task-manager\src\app\exceptions\decorators.py:47 - Unexpected server error: password cannot be longer than 72 bytes, truncate manually if necessary (e.g. my_password[:72]), traceback=<traceback object at 0x0000022176977100>
2025-10-26 23:45:39,375 - task_manager - CRITICAL - c:\Users\pmokr\OneDrive\Рабочий стол\task-manager\src\app\exceptions\decorators.py:47 - Unexpected server error: password cannot be longer than 72 bytes, truncate manually if necessary (e.g. my_password[:72]), traceback=<traceback object at 0x0000022176977100>
2025-10-26 23:45:39,685 - task_manager - CRITICAL - c:\Users\pmokr\OneDrive\Рабочий стол\task-manager\src\app\exceptions\decorators.py:47 - Unexpected server error: (sqlite3.IntegrityError) UNIQUE constraint failed: users.email
[SQL: INSERT INTO users (first_name, last_name, email, password_hash, role, active, id) VALUES (?, ?, ?, ?, ?, ?, ?) RETURNING created_at, updated_at]
[parameters: ('мин', 'пароль', 'minpassword@example.com', b'$2b$12$ytH0XQJcKJh01ZlYC5eF/uHIEzTPRzSS0BkPPnWwfNjmVekJZoNh2', 'user', 1, '729c262716474dd08ffc7e425dfffd03')]
(Background on this error at: https://sqlalche.me/e/20/gkpj), traceback=<traceback object at 0x0000022177BAD4C0>
2025-10-26 23:45:39,685 - task_manager - CRITICAL - c:\Users\pmokr\OneDrive\Рабочий стол\task-manager\src\app\exceptions\decorators.py:47 - Unexpected server error: (sqlite3.IntegrityError) UNIQUE constraint failed: users.email
[SQL: INSERT INTO users (first_name, last_name, email, password_hash, role, active, id) VALUES (?, ?, ?, ?, ?, ?, ?) RETURNING created_at, updated_at]
[parameters: ('мин', 'пароль', 'minpassword@example.com', b'$2b$12$ytH0XQJcKJh01ZlYC5eF/uHIEzTPRzSS0BkPPnWwfNjmVekJZoNh2', 'user', 1, '729c262716474dd08ffc7e425dfffd03')]
(Background on this error at: https://sqlalche.me/e/20/gkpj), traceback=<traceback object at 0x0000022177BAD4C0>
2025-10-26 23:45:40,441 - task_manager - CRITICAL - c:\Users\pmokr\OneDrive\Рабочий стол\task-manager\src\app\exceptions\decorators.py:47 - Unexpected server error: (sqlite3.IntegrityError) UNIQUE constraint failed: users.email
[SQL: INSERT INTO users (first_name, last_name, email, password_hash, role, active, id) VALUES (?, ?, ?, ?, ?, ?, ?) RETURNING created_at, updated_at]
[parameters: ('тест', 'обновление', 'update.extra@example.com', b'$2b$12$gc2.OXZNCchS9AekDjixEOoc9IHLvh24eHY/Qo8drmErrEof6vt7q', 'user', 1, '6aadb70d3aeb48a5b42c6ed885ef1571')]
(Background on this error at: https://sqlalche.me/e/20/gkpj), traceback=<traceback object at 0x000002217775CCC0>
2025-10-26 23:45:40,441 - task_manager - CRITICAL - c:\Users\pmokr\OneDrive\Рабочий стол\task-manager\src\app\exceptions\decorators.py:47 - Unexpected server error: (sqlite3.IntegrityError) UNIQUE constraint failed: users.email
[SQL: INSERT INTO users (first_name, last_name, email, password_hash, role, active, id) VALUES (?, ?, ?, ?, ?, ?, ?) RETURNING created_at, updated_at]
[parameters: ('тест', 'обновление', 'update.extra@example.com', b'$2b$12$gc2.OXZNCchS9AekDjixEOoc9IHLvh24eHY/Qo8drmErrEof6vt7q', 'user', 1, '6aadb70d3aeb48a5b42c6ed885ef1571')]
(Background on this error at: https://sqlalche.me/e/20/gkpj), traceback=<traceback object at 0x000002217775CCC0>
2025-10-26 23:45:40,870 - task_manager - CRITICAL - c:\Users\pmokr\OneDrive\Рабочий стол\task-manager\src\app\exceptions\decorators.py:47 - Unexpected server error: (sqlite3.IntegrityError) UNIQUE constraint failed: users.email
[SQL: INSERT INTO users (first_name, last_name, email, password_hash, role, active, id) VALUES (?, ?, ?, ?, ?, ?, ?) RETURNING created_at, updated_at]
[parameters: ('регистр', 'тест', 'casesensitive@example.com', b'$2b$12$RYs2RX7lwaUHtc3ftZPMaOpH0.Ql14LUV/54a1axrf2fVgDKLHAvi', 'user', 1, '3a40515c0d3742deba8c461b9de12927')]
(Background on this error at: https://sqlalche.me/e/20/gkpj), traceback=<traceback object at 0x000002217644A800>
2025-10-26 23:45:40,870 - task_manager - CRITICAL - c:\Users\pmokr\OneDrive\Рабочий стол\task-manager\src\app\exceptions\decorators.py:47 - Unexpected server error: (sqlite3.IntegrityError) UNIQUE constraint failed: users.email
[SQL: INSERT INTO users (first_name, last_name, email, password_hash, role, active, id) VALUES (?, ?, ?, ?, ?, ?, ?) RETURNING created_at, updated_at]
[parameters: ('регистр', 'тест', 'casesensitive@example.com', b'$2b$12$RYs2RX7lwaUHtc3ftZPMaOpH0.Ql14LUV/54a1axrf2fVgDKLHAvi', 'user', 1, '3a40515c0d3742deba8c461b9de12927')]
(Background on this error at: https://sqlalche.me/e/20/gkpj), traceback=<traceback object at 0x000002217644A800>
2025-10-26 23:45:42,072 - task_manager - CRITICAL - c:\Users\pmokr\OneDrive\Рабочий стол\task-manager\src\app\exceptions\decorators.py:47 - Unexpected server error: 'user' is not among the defined enum values. Enum name: role. Possible values: USER, ADMIN, traceback=<traceback object at 0x00000221765046C0>
2025-10-26 23:45:42,072 - task_manager - CRITICAL - c:\Users\pmokr\OneDrive\Рабочий стол\task-manager\src\app\exceptions\decorators.py:47 - Unexpected server error: 'user' is not among the defined enum values. Enum name: role. Possible values: USER, ADMIN, traceback=<traceback object at 0x00000221765046C0>
2025-10-26 23:45:43,763 - task_manager - CRITICAL - c:\Users\pmokr\OneDrive\Рабочий стол\task-manager\src\app\exceptions\decorators.py:47 - Unexpected server error: 'user' is not among the defined enum values. Enum name: role. Possible values: USER, ADMIN, traceback=<traceback object at 0x0000022177EEF040>
2025-10-26 23:45:43,763 - task_manager - CRITICAL - c:\Users\pmokr\OneDrive\Рабочий стол\task-manager\src\app\exceptions\decorators.py:47 - Unexpected server error: 'user' is not among the defined enum values. Enum name: role. Possible values: USER, ADMIN, traceback=<traceback object at 0x0000022177EEF040>
2025-10-26 23:45:44,140 - task_manager - CRITICAL - c:\Users\pmokr\OneDrive\Рабочий стол\task-manager\src\app\exceptions\decorators.py:47 - Unexpected server error: 'user' is not among the defined enum values. Enum name: role. Possible values: USER, ADMIN, traceback=<traceback object at 0x0000022176782A40>
2025-10-26 23:45:44,140 - task_manager - CRITICAL - c:\Users\pmokr\OneDrive\Рабочий стол\task-manager\src\app\exceptions\decorators.py:47 - Unexpected server error: 'user' is not among the defined enum values. Enum name: role. Possible values: USER, ADMIN, traceback=<traceback object at 0x0000022176782A40>
2025-10-26 23:45:44,719 - task_manager - CRITICAL - c:\Users\pmokr\OneDrive\Рабочий стол\task-manager\src\app\exceptions\decorators.py:47 - Unexpected server error: 'user' is not among the defined enum values. Enum name: role. Possible values: USER, ADMIN, traceback=<traceback object at 0x0000022177E69040>
2025-10-26 23:45:44,719 - task_manager - CRITICAL - c:\Users\pmokr\OneDrive\Рабочий стол\task-manager\src\app\exceptions\decorators.py:47 - Unexpected server error: 'user' is not among the defined enum values. Enum name: role. Possible values: USER, ADMIN, traceback=<traceback object at 0x0000022177E69040>
2025-10-26 23:45:45,084 - task_manager - CRITICAL - c:\Users\pmokr\OneDrive\Рабочий стол\task-manager\src\app\exceptions\decorators.py:47 - Unexpected server error: 'user' is not among the defined enum values. Enum name: role. Possible values: USER, ADMIN, traceback=<traceback object at 0x0000022177805540>
2025-10-26 23:45:45,084 - task_manager - CRITICAL - c:\Users\pmokr\OneDrive\Рабочий стол\task-manager\src\app\exceptions\decorators.py:47 - Unexpected server error: 'user' is not among the defined enum values. Enum name: role. Possible values: USER, ADMIN, traceback=<traceback object at 0x0000022177805540>
2025-10-26 23:55:35,771 - task_manager - CRITICAL - c:\Users\pmokr\OneDrive\Рабочий стол\task-manager\src\app\exceptions\decorators.py:47 - Unexpected server error: 'user' is not among the defined enum values. Enum name: role. Possible values: USER, ADMIN, traceback=<traceback object at 0x0000021F24E1A840>
2025-10-26 23:55:35,771 - task_manager - CRITICAL - c:\Users\pmokr\OneDrive\Рабочий стол\task-manager\src\app\exceptions\decorators.py:47 - Unexpected server error: 'user' is not among the defined enum values. Enum name: role. Possible values: USER, ADMIN, traceback=<traceback object at 0x0000021F24E1A840>
2025-10-26 23:55:35,886 - task_manager - CRITICAL - c:\Users\pmokr\OneDrive\Рабочий стол\task-manager\src\app\exceptions\decorators.py:47 - Unexpected server error: 'user' is not among the defined enum values. Enum name: role. Possible values: USER, ADMIN, traceback=<traceback object at 0x0000021F2511BFC0>
2025-10-26 23:55:35,886 - task_manager - CRITICAL - c:\Users\pmokr\OneDrive\Рабочий стол\task-manager\src\app\exceptions\decorators.py:47 - Unexpected server error: 'user' is not among the defined enum values. Enum name: role. Possible values: USER, ADMIN, traceback=<traceback object at 0x0000021F2511BFC0>
2025-10-27 00:01:02,948 - task_manager - CRITICAL - c:\Users\pmokr\OneDrive\Рабочий стол\task-manager\src\app\exceptions\decorators.py:47 - Unexpected server error: 'user' is not among the defined enum values. Enum name: role. Possible values: USER, ADMIN, traceback=<traceback object at 0x00000220A7797600>
2025-10-27 00:01:02,948 - task_manager - CRITICAL - c:\Users\pmokr\OneDrive\Рабочий стол\task-manager\src\app\exceptions\decorators.py:47 - Unexpected server error: 'user' is not among the defined enum values. Enum name: role. Possible values: USER, ADMIN, traceback=<traceback object at 0x00000220A7797600>
2025-10-27 00:01:03,059 - task_manager - CRITICAL - c:\Users\pmokr\OneDrive\Рабочий стол\task-manager\src\app\exceptions\decorators.py:47 - Unexpected server error: 'user' is not among the defined enum values. Enum name: role. Possible values: USER, ADMIN, traceback=<traceback object at 0x00000220A7725FC0>
2025-10-27 00:01:03,059 - task_manager - CRITICAL - c:\Users\pmokr\OneDrive\Рабочий стол\task-manager\src\app\exceptions\decorators.py:47 - Unexpected server error: 'user' is not among the defined enum values. Enum name: role. Possible values: USER, ADMIN, traceback=<traceback object at 0x00000220A7725FC0>
2025-10-27 00:13:16,028 - task_manager - CRITICAL - c:\Users\pmokr\OneDrive\Рабочий стол\task-manager\src\app\exceptions\decorators.py:47 - Unexpected server error: 1 validation error for UserOut
role
  Value error, Invalid role value: user [type=value_error, input_value='user', input_type=str]
    For further information visit https://errors.pydantic.dev/2.11/v/value_error, traceback=<traceback object at 0x000001F3610E3C40>
2025-10-27 00:13:16,028 - task_manager - CRITICAL - c:\Users\pmokr\OneDrive\Рабочий стол\task-manager\src\app\exceptions\decorators.py:47 - Unexpected server error: 1 validation error for UserOut
role
  Value error, Invalid role value: user [type=value_error, input_value='user', input_type=str]
    For further information visit https://errors.pydantic.dev/2.11/v/value_error, traceback=<traceback object at 0x000001F3610E3C40>
2025-10-27 00:13:16,152 - task_manager - CRITICAL - c:\Users\pmokr\OneDrive\Рабочий стол\task-manager\src\app\exceptions\decorators.py:47 - Unexpected server error: 1 validation error for UserOut
role
  Value error, Invalid role value: user [type=value_error, input_value='user', input_type=str]
    For further information visit https://errors.pydantic.dev/2.11/v/value_error, traceback=<traceback object at 0x000001F3610827C0>
2025-10-27 00:13:16,152 - task_manager - CRITICAL - c:\Users\pmokr\OneDrive\Рабочий стол\task-manager\src\app\exceptions\decorators.py:47 - Unexpected server error: 1 validation error for UserOut
role
  Value error, Invalid role value: user [type=value_error, input_value='user', input_type=str]
    For further information visit https://errors.pydantic.dev/2.11/v/value_error, traceback=<traceback object at 0x000001F3610827C0>
